Exception on /home [GET]
Traceback (most recent call last):
  File "/usr/local/lib/python2.7/dist-packages/flask/app.py", line 1817, in wsgi_app
    response = self.full_dispatch_request()
  File "/usr/local/lib/python2.7/dist-packages/flask/app.py", line 1477, in full_dispatch_request
    rv = self.handle_user_exception(e)
  File "/usr/local/lib/python2.7/dist-packages/flask/app.py", line 1381, in handle_user_exception
    reraise(exc_type, exc_value, tb)
  File "/usr/local/lib/python2.7/dist-packages/flask/app.py", line 1475, in full_dispatch_request
    rv = self.dispatch_request()
  File "/usr/local/lib/python2.7/dist-packages/flask/app.py", line 1461, in dispatch_request
    return self.view_functions[rule.endpoint](**req.view_args)
  File "/usr/local/lib/python2.7/dist-packages/flask_login.py", line 757, in decorated_view
    return current_app.login_manager.unauthorized()
  File "/usr/local/lib/python2.7/dist-packages/flask_login.py", line 205, in unauthorized
    return redirect(login_url(self.login_view, request.url))
  File "/usr/local/lib/python2.7/dist-packages/flask_login.py", line 609, in login_url
    base = url_for(login_view)
  File "/usr/local/lib/python2.7/dist-packages/flask/helpers.py", line 312, in url_for
    return appctx.app.handle_url_build_error(error, endpoint, values)
  File "/usr/local/lib/python2.7/dist-packages/flask/app.py", line 1641, in handle_url_build_error
    reraise(exc_type, exc_value, tb)
  File "/usr/local/lib/python2.7/dist-packages/flask/helpers.py", line 305, in url_for
    force_external=external)
  File "/usr/local/lib/python2.7/dist-packages/werkzeug/routing.py", line 1678, in build
    raise BuildError(endpoint, values, method)
BuildError: ('login', {}, None)
Exception on /home [GET]
Traceback (most recent call last):
  File "/usr/local/lib/python2.7/dist-packages/flask/app.py", line 1817, in wsgi_app
    response = self.full_dispatch_request()
  File "/usr/local/lib/python2.7/dist-packages/flask/app.py", line 1477, in full_dispatch_request
    rv = self.handle_user_exception(e)
  File "/usr/local/lib/python2.7/dist-packages/flask/app.py", line 1381, in handle_user_exception
    reraise(exc_type, exc_value, tb)
  File "/usr/local/lib/python2.7/dist-packages/flask/app.py", line 1475, in full_dispatch_request
    rv = self.dispatch_request()
  File "/usr/local/lib/python2.7/dist-packages/flask/app.py", line 1461, in dispatch_request
    return self.view_functions[rule.endpoint](**req.view_args)
  File "/usr/local/lib/python2.7/dist-packages/flask_login.py", line 758, in decorated_view
    return func(*args, **kwargs)
  File "/opt/aquarium/app/views.py", line 32, in home
    user=g.user)
  File "/usr/local/lib/python2.7/dist-packages/flask/templating.py", line 128, in render_template
    context, ctx.app)
  File "/usr/local/lib/python2.7/dist-packages/flask/templating.py", line 110, in _render
    rv = template.render(context)
  File "/usr/local/lib/python2.7/dist-packages/jinja2/environment.py", line 969, in render
    return self.environment.handle_exception(exc_info, True)
  File "/usr/local/lib/python2.7/dist-packages/jinja2/environment.py", line 742, in handle_exception
    reraise(exc_type, exc_value, tb)
  File "/opt/aquarium/app/templates/base.html", line 9, in template
    <script type="text/javascript" src="{{ url_for('static', filename='/js/widgets.js' }}"></script>
TemplateSyntaxError: unexpected '}', expected ')'
Exception on /home [GET]
Traceback (most recent call last):
  File "/usr/local/lib/python2.7/dist-packages/flask/app.py", line 1817, in wsgi_app
    response = self.full_dispatch_request()
  File "/usr/local/lib/python2.7/dist-packages/flask/app.py", line 1477, in full_dispatch_request
    rv = self.handle_user_exception(e)
  File "/usr/local/lib/python2.7/dist-packages/flask/app.py", line 1381, in handle_user_exception
    reraise(exc_type, exc_value, tb)
  File "/usr/local/lib/python2.7/dist-packages/flask/app.py", line 1475, in full_dispatch_request
    rv = self.dispatch_request()
  File "/usr/local/lib/python2.7/dist-packages/flask/app.py", line 1461, in dispatch_request
    return self.view_functions[rule.endpoint](**req.view_args)
  File "/usr/local/lib/python2.7/dist-packages/flask_login.py", line 758, in decorated_view
    return func(*args, **kwargs)
  File "/opt/aquarium/app/views.py", line 32, in home
    user=g.user)
  File "/usr/local/lib/python2.7/dist-packages/flask/templating.py", line 128, in render_template
    context, ctx.app)
  File "/usr/local/lib/python2.7/dist-packages/flask/templating.py", line 110, in _render
    rv = template.render(context)
  File "/usr/local/lib/python2.7/dist-packages/jinja2/environment.py", line 969, in render
    return self.environment.handle_exception(exc_info, True)
  File "/usr/local/lib/python2.7/dist-packages/jinja2/environment.py", line 742, in handle_exception
    reraise(exc_type, exc_value, tb)
  File "/opt/aquarium/app/templates/base.html", line 9, in template
    <script type="text/javascript" src="{{ url_for('static', filename='/js/widgets.js' }}"></script>
TemplateSyntaxError: unexpected '}', expected ')'
Exception on /home [GET]
Traceback (most recent call last):
  File "/usr/local/lib/python2.7/dist-packages/flask/app.py", line 1817, in wsgi_app
    response = self.full_dispatch_request()
  File "/usr/local/lib/python2.7/dist-packages/flask/app.py", line 1477, in full_dispatch_request
    rv = self.handle_user_exception(e)
  File "/usr/local/lib/python2.7/dist-packages/flask/app.py", line 1381, in handle_user_exception
    reraise(exc_type, exc_value, tb)
  File "/usr/local/lib/python2.7/dist-packages/flask/app.py", line 1475, in full_dispatch_request
    rv = self.dispatch_request()
  File "/usr/local/lib/python2.7/dist-packages/flask/app.py", line 1461, in dispatch_request
    return self.view_functions[rule.endpoint](**req.view_args)
  File "/usr/local/lib/python2.7/dist-packages/flask_login.py", line 758, in decorated_view
    return func(*args, **kwargs)
  File "/opt/aquarium/app/views.py", line 32, in home
    user=g.user)
  File "/usr/local/lib/python2.7/dist-packages/flask/templating.py", line 128, in render_template
    context, ctx.app)
  File "/usr/local/lib/python2.7/dist-packages/flask/templating.py", line 110, in _render
    rv = template.render(context)
  File "/usr/local/lib/python2.7/dist-packages/jinja2/environment.py", line 969, in render
    return self.environment.handle_exception(exc_info, True)
  File "/usr/local/lib/python2.7/dist-packages/jinja2/environment.py", line 742, in handle_exception
    reraise(exc_type, exc_value, tb)
  File "/opt/aquarium/app/templates/base.html", line 9, in template
    <script type="text/javascript" src="{{ url_for('static', filename='/js/widgets.js' }}"></script>
TemplateSyntaxError: unexpected '}', expected ')'
Exception on /chat [GET]
Traceback (most recent call last):
  File "/usr/local/lib/python2.7/dist-packages/flask/app.py", line 1817, in wsgi_app
    response = self.full_dispatch_request()
  File "/usr/local/lib/python2.7/dist-packages/flask/app.py", line 1477, in full_dispatch_request
    rv = self.handle_user_exception(e)
  File "/usr/local/lib/python2.7/dist-packages/flask/app.py", line 1381, in handle_user_exception
    reraise(exc_type, exc_value, tb)
  File "/usr/local/lib/python2.7/dist-packages/flask/app.py", line 1475, in full_dispatch_request
    rv = self.dispatch_request()
  File "/usr/local/lib/python2.7/dist-packages/flask/app.py", line 1461, in dispatch_request
    return self.view_functions[rule.endpoint](**req.view_args)
  File "/usr/local/lib/python2.7/dist-packages/flask_login.py", line 758, in decorated_view
    return func(*args, **kwargs)
  File "/opt/aquarium/app/views.py", line 84, in chat
    return render_template('chat.html', form=form, posts=posts, onlineUsers=onlineUsers)
  File "/usr/local/lib/python2.7/dist-packages/flask/templating.py", line 128, in render_template
    context, ctx.app)
  File "/usr/local/lib/python2.7/dist-packages/flask/templating.py", line 110, in _render
    rv = template.render(context)
  File "/usr/local/lib/python2.7/dist-packages/jinja2/environment.py", line 969, in render
    return self.environment.handle_exception(exc_info, True)
  File "/usr/local/lib/python2.7/dist-packages/jinja2/environment.py", line 742, in handle_exception
    reraise(exc_type, exc_value, tb)
  File "/opt/aquarium/app/templates/base.html", line 9, in template
    <script type="text/javascript" src="{{ url_for('static', filename='/js/widgets.js' }}"></script>
TemplateSyntaxError: unexpected '}', expected ')'
Exception on /home [GET]
Traceback (most recent call last):
  File "/usr/local/lib/python2.7/dist-packages/flask/app.py", line 1817, in wsgi_app
    response = self.full_dispatch_request()
  File "/usr/local/lib/python2.7/dist-packages/flask/app.py", line 1477, in full_dispatch_request
    rv = self.handle_user_exception(e)
  File "/usr/local/lib/python2.7/dist-packages/flask/app.py", line 1381, in handle_user_exception
    reraise(exc_type, exc_value, tb)
  File "/usr/local/lib/python2.7/dist-packages/flask/app.py", line 1475, in full_dispatch_request
    rv = self.dispatch_request()
  File "/usr/local/lib/python2.7/dist-packages/flask/app.py", line 1461, in dispatch_request
    return self.view_functions[rule.endpoint](**req.view_args)
  File "/usr/local/lib/python2.7/dist-packages/flask_login.py", line 758, in decorated_view
    return func(*args, **kwargs)
  File "/opt/aquarium/app/views.py", line 32, in home
    user=g.user)
  File "/usr/local/lib/python2.7/dist-packages/flask/templating.py", line 128, in render_template
    context, ctx.app)
  File "/usr/local/lib/python2.7/dist-packages/flask/templating.py", line 110, in _render
    rv = template.render(context)
  File "/usr/local/lib/python2.7/dist-packages/jinja2/environment.py", line 969, in render
    return self.environment.handle_exception(exc_info, True)
  File "/usr/local/lib/python2.7/dist-packages/jinja2/environment.py", line 742, in handle_exception
    reraise(exc_type, exc_value, tb)
  File "/opt/aquarium/app/templates/base.html", line 9, in template
    <script type="text/javascript" src="{{ url_for('static', filename='/js/widgets.js' }}"></script>
TemplateSyntaxError: unexpected '}', expected ')'
Exception on /home [GET]
Traceback (most recent call last):
  File "/usr/local/lib/python2.7/dist-packages/flask/app.py", line 1817, in wsgi_app
    response = self.full_dispatch_request()
  File "/usr/local/lib/python2.7/dist-packages/flask/app.py", line 1477, in full_dispatch_request
    rv = self.handle_user_exception(e)
  File "/usr/local/lib/python2.7/dist-packages/flask/app.py", line 1381, in handle_user_exception
    reraise(exc_type, exc_value, tb)
  File "/usr/local/lib/python2.7/dist-packages/flask/app.py", line 1475, in full_dispatch_request
    rv = self.dispatch_request()
  File "/usr/local/lib/python2.7/dist-packages/flask/app.py", line 1461, in dispatch_request
    return self.view_functions[rule.endpoint](**req.view_args)
  File "/usr/local/lib/python2.7/dist-packages/flask_login.py", line 758, in decorated_view
    return func(*args, **kwargs)
  File "/opt/aquarium/app/views.py", line 32, in home
    user=g.user)
  File "/usr/local/lib/python2.7/dist-packages/flask/templating.py", line 128, in render_template
    context, ctx.app)
  File "/usr/local/lib/python2.7/dist-packages/flask/templating.py", line 110, in _render
    rv = template.render(context)
  File "/usr/local/lib/python2.7/dist-packages/jinja2/environment.py", line 969, in render
    return self.environment.handle_exception(exc_info, True)
  File "/usr/local/lib/python2.7/dist-packages/jinja2/environment.py", line 742, in handle_exception
    reraise(exc_type, exc_value, tb)
  File "/opt/aquarium/app/templates/index.html", line 1, in top-level template code
    {% extends "base.html" %}
  File "/usr/local/lib/python2.7/dist-packages/flask/templating.py", line 64, in get_source
    raise TemplateNotFound(template)
TemplateNotFound: base.html
Exception on /home [GET]
Traceback (most recent call last):
  File "/usr/local/lib/python2.7/dist-packages/flask/app.py", line 1817, in wsgi_app
    response = self.full_dispatch_request()
  File "/usr/local/lib/python2.7/dist-packages/flask/app.py", line 1477, in full_dispatch_request
    rv = self.handle_user_exception(e)
  File "/usr/local/lib/python2.7/dist-packages/flask/app.py", line 1381, in handle_user_exception
    reraise(exc_type, exc_value, tb)
  File "/usr/local/lib/python2.7/dist-packages/flask/app.py", line 1473, in full_dispatch_request
    rv = self.preprocess_request()
  File "/usr/local/lib/python2.7/dist-packages/flask/app.py", line 1666, in preprocess_request
    rv = func()
  File "/opt/aquarium/app/views.py", line 49, in before_request
    db.session.commit()
  File "/usr/local/lib/python2.7/dist-packages/sqlalchemy/orm/scoping.py", line 150, in do
    return getattr(self.registry(), name)(*args, **kwargs)
  File "/usr/local/lib/python2.7/dist-packages/sqlalchemy/orm/session.py", line 788, in commit
    self.transaction.commit()
  File "/usr/local/lib/python2.7/dist-packages/sqlalchemy/orm/session.py", line 384, in commit
    self._prepare_impl()
  File "/usr/local/lib/python2.7/dist-packages/sqlalchemy/orm/session.py", line 364, in _prepare_impl
    self.session.flush()
  File "/usr/local/lib/python2.7/dist-packages/sqlalchemy/orm/session.py", line 1985, in flush
    self._flush(objects)
  File "/usr/local/lib/python2.7/dist-packages/sqlalchemy/orm/session.py", line 2103, in _flush
    transaction.rollback(_capture_exception=True)
  File "/usr/local/lib/python2.7/dist-packages/sqlalchemy/util/langhelpers.py", line 60, in __exit__
    compat.reraise(exc_type, exc_value, exc_tb)
  File "/usr/local/lib/python2.7/dist-packages/sqlalchemy/orm/session.py", line 2067, in _flush
    flush_context.execute()
  File "/usr/local/lib/python2.7/dist-packages/sqlalchemy/orm/unitofwork.py", line 372, in execute
    rec.execute(self)
  File "/usr/local/lib/python2.7/dist-packages/sqlalchemy/orm/unitofwork.py", line 526, in execute
    uow
  File "/usr/local/lib/python2.7/dist-packages/sqlalchemy/orm/persistence.py", line 60, in save_obj
    mapper, table, update)
  File "/usr/local/lib/python2.7/dist-packages/sqlalchemy/orm/persistence.py", line 518, in _emit_update_statements
    execute(statement, params)
  File "/usr/local/lib/python2.7/dist-packages/sqlalchemy/engine/base.py", line 841, in execute
    return meth(self, multiparams, params)
  File "/usr/local/lib/python2.7/dist-packages/sqlalchemy/sql/elements.py", line 322, in _execute_on_connection
    return connection._execute_clauseelement(self, multiparams, params)
  File "/usr/local/lib/python2.7/dist-packages/sqlalchemy/engine/base.py", line 938, in _execute_clauseelement
    compiled_sql, distilled_params
  File "/usr/local/lib/python2.7/dist-packages/sqlalchemy/engine/base.py", line 1070, in _execute_context
    context)
  File "/usr/local/lib/python2.7/dist-packages/sqlalchemy/engine/base.py", line 1271, in _handle_dbapi_exception
    exc_info
  File "/usr/local/lib/python2.7/dist-packages/sqlalchemy/util/compat.py", line 199, in raise_from_cause
    reraise(type(exception), exception, tb=exc_tb)
  File "/usr/local/lib/python2.7/dist-packages/sqlalchemy/engine/base.py", line 1063, in _execute_context
    context)
  File "/usr/local/lib/python2.7/dist-packages/sqlalchemy/engine/default.py", line 442, in do_execute
    cursor.execute(statement, parameters)
OperationalError: (OperationalError) database is locked u'UPDATE user SET last_poll=? WHERE user.id = ?' ('2015-05-28 10:40:12.036628', 1)
